<sdf version='1.9'>
  <model name='eclipse_ackermann_bot'>
    <link name='base_link'>
      <inertial>
        <pose>0 0 0.001086956521739131 0 0 0</pose>
        <mass>5.0599999999999996</mass>
        <inertia>
          <ixx>0.050629021739130441</ixx>
          <ixy>0</ixy>
          <ixz>0</ixz>
          <iyy>0.050629021739130441</iyy>
          <iyz>0</iyz>
          <izz>0.050110000000000009</izz>
        </inertia>
      </inertial>
      <collision name='base_link_collision'>
        <pose>0 0 0 0 0 0</pose>
        <geometry>
          <box>
            <size>0.4 0.25 0.1</size>
          </box>
        </geometry>
      </collision>
      <collision name='base_link_fixed_joint_lump__lidar_link_collision_1'>
        <pose>0 0 0.1 0 0 0</pose>
        <geometry>
          <cylinder>
            <length>0.050000000000000003</length>
            <radius>0.029999999999999999</radius>
          </cylinder>
        </geometry>
        <surface>
          <contact>
            <ode/>
          </contact>
          <friction>
            <ode/>
          </friction>
        </surface>
      </collision>
      <visual name='base_link_visual'>
        <pose>0 0 0 0 0 0</pose>
        <geometry>
          <box>
            <size>0.4 0.25 0.1</size>
          </box>
        </geometry>
        <material>
          <diffuse>0 0.375 1 1</diffuse>
          <ambient>0 0.375 1 1</ambient>
        </material>
      </visual>
      <visual name='base_link_fixed_joint_lump__lidar_link_visual_1'>
        <pose>0 0 0.1 0 0 0</pose>
        <geometry>
          <cylinder>
            <length>0.050000000000000003</length>
            <radius>0.029999999999999999</radius>
          </cylinder>
        </geometry>
        <material>
          <diffuse>1 1 1 1</diffuse>
          <ambient>1 1 1 1</ambient>
        </material>
      </visual>
      <sensor name='imu_sensor' type='imu'>
        <always_on>true</always_on>
        <update_rate>100</update_rate>
        <topic>imu</topic>
        <imu>
          <angular_velocity>
            <x>
              <noise type='gaussian'>
                <mean>0</mean>
                <stddev>0.01</stddev>
              </noise>
            </x>
            <y>
              <noise type='gaussian'>
                <mean>0</mean>
                <stddev>0.01</stddev>
              </noise>
            </y>
            <z>
              <noise type='gaussian'>
                <mean>0</mean>
                <stddev>0.01</stddev>
              </noise>
            </z>
          </angular_velocity>
          <linear_acceleration>
            <x>
              <noise type='gaussian'>
                <mean>0</mean>
                <stddev>0.10000000000000001</stddev>
              </noise>
            </x>
            <y>
              <noise type='gaussian'>
                <mean>0</mean>
                <stddev>0.10000000000000001</stddev>
              </noise>
            </y>
            <z>
              <noise type='gaussian'>
                <mean>0</mean>
                <stddev>0.10000000000000001</stddev>
              </noise>
            </z>
          </linear_acceleration>
        </imu>
        <pose>0 0 0.05 0 -0 0</pose>
      </sensor>
      <sensor name='lidar_sensor' type='gpu_lidar'>
        <always_on>true</always_on>
        <update_rate>10</update_rate>
        <visualize>true</visualize>
        <topic>scan</topic>
        <ray>
          <scan>
            <horizontal>
              <samples>720</samples>
              <resolution>1</resolution>
              <min_angle>-1.5708</min_angle>
              <max_angle>1.5708</max_angle>
            </horizontal>
          </scan>
          <range>
            <min>0.12</min>
            <max>5</max>
            <resolution>0.01</resolution>
          </range>
          <noise>
            <type>gaussian</type>
            <stddev>0.01</stddev>
          </noise>
        </ray>
        <plugin name='gz::sim::systems::Sensors' filename='gz-sim-sensors-system'/>
        <pose>0 0 0.1 0 -0 0</pose>
      </sensor>
    </link>
    <joint name='front_left_wheel_steering_joint' type='revolute'>
      <pose relative_to='base_link'>0.15 0.125 0 0 0 0</pose>
      <parent>base_link</parent>
      <child>front_left_wheel_steering_link</child>
      <axis>
        <xyz>0 0 1</xyz>
        <limit>
          <lower>-0.59999999999999998</lower>
          <upper>0.59999999999999998</upper>
          <effort>100</effort>
          <velocity>10</velocity>
        </limit>
        <dynamics>
          <spring_reference>0</spring_reference>
          <spring_stiffness>0</spring_stiffness>
        </dynamics>
      </axis>
    </joint>
    <link name='front_left_wheel_steering_link'>
      <pose relative_to='front_left_wheel_steering_joint'>0 0 0 0 0 0</pose>
      <inertial>
        <pose>0 0 0 0 0 0</pose>
        <mass>0.01</mass>
        <inertia>
          <ixx>1.0000000000000001e-05</ixx>
          <ixy>0</ixy>
          <ixz>0</ixz>
          <iyy>1.0000000000000001e-05</iyy>
          <iyz>0</iyz>
          <izz>1.0000000000000001e-05</izz>
        </inertia>
      </inertial>
    </link>
    <joint name='front_left_wheel_joint' type='revolute'>
      <pose relative_to='front_left_wheel_steering_link'>0 0 0 0 0 0</pose>
      <parent>front_left_wheel_steering_link</parent>
      <child>front_left_wheel</child>
      <axis>
        <xyz>0 1 0</xyz>
        <limit>
          <lower>-10000000000000000</lower>
          <upper>10000000000000000</upper>
        </limit>
        <dynamics>
          <spring_reference>0</spring_reference>
          <spring_stiffness>0</spring_stiffness>
        </dynamics>
      </axis>
    </joint>
    <link name='front_left_wheel'>
      <pose relative_to='front_left_wheel_joint'>0 0 0 0 0 0</pose>
      <inertial>
        <pose>0 0 0 0 0 0</pose>
        <mass>0.5</mass>
        <inertia>
          <ixx>0.001</ixx>
          <ixy>0</ixy>
          <ixz>0</ixz>
          <iyy>0.001</iyy>
          <iyz>0</iyz>
          <izz>0.00050000000000000001</izz>
        </inertia>
      </inertial>
      <collision name='front_left_wheel_collision'>
        <pose>0 0 0 1.5708 0 0</pose>
        <geometry>
          <cylinder>
            <length>0.029999999999999999</length>
            <radius>0.050000000000000003</radius>
          </cylinder>
        </geometry>
        <surface>
          <contact>
            <ode>
              <kp>1000000</kp>
              <kd>100</kd>
              <max_vel>1</max_vel>
              <min_depth>0.001</min_depth>
            </ode>
          </contact>
          <friction>
            <ode>
              <mu>1.2</mu>
              <mu2>1.2</mu2>
            </ode>
          </friction>
        </surface>
      </collision>
      <visual name='front_left_wheel_visual'>
        <pose>0 0 0 1.5708 0 0</pose>
        <geometry>
          <cylinder>
            <length>0.029999999999999999</length>
            <radius>0.050000000000000003</radius>
          </cylinder>
        </geometry>
        <material>
          <diffuse>0 0 0 1</diffuse>
          <ambient>0 0 0 1</ambient>
        </material>
      </visual>
    </link>
    <joint name='front_right_wheel_steering_joint' type='revolute'>
      <pose relative_to='base_link'>0.15 -0.125 0 0 0 0</pose>
      <parent>base_link</parent>
      <child>front_right_wheel_steering_link</child>
      <axis>
        <xyz>0 0 1</xyz>
        <limit>
          <lower>-0.59999999999999998</lower>
          <upper>0.59999999999999998</upper>
          <effort>100</effort>
          <velocity>10</velocity>
        </limit>
        <dynamics>
          <spring_reference>0</spring_reference>
          <spring_stiffness>0</spring_stiffness>
        </dynamics>
      </axis>
    </joint>
    <link name='front_right_wheel_steering_link'>
      <pose relative_to='front_right_wheel_steering_joint'>0 0 0 0 0 0</pose>
      <inertial>
        <pose>0 0 0 0 0 0</pose>
        <mass>0.01</mass>
        <inertia>
          <ixx>1.0000000000000001e-05</ixx>
          <ixy>0</ixy>
          <ixz>0</ixz>
          <iyy>1.0000000000000001e-05</iyy>
          <iyz>0</iyz>
          <izz>1.0000000000000001e-05</izz>
        </inertia>
      </inertial>
    </link>
    <joint name='front_right_wheel_joint' type='revolute'>
      <pose relative_to='front_right_wheel_steering_link'>0 0 0 0 0 0</pose>
      <parent>front_right_wheel_steering_link</parent>
      <child>front_right_wheel</child>
      <axis>
        <xyz>0 1 0</xyz>
        <limit>
          <lower>-10000000000000000</lower>
          <upper>10000000000000000</upper>
        </limit>
        <dynamics>
          <spring_reference>0</spring_reference>
          <spring_stiffness>0</spring_stiffness>
        </dynamics>
      </axis>
    </joint>
    <link name='front_right_wheel'>
      <pose relative_to='front_right_wheel_joint'>0 0 0 0 0 0</pose>
      <inertial>
        <pose>0 0 0 0 0 0</pose>
        <mass>0.5</mass>
        <inertia>
          <ixx>0.001</ixx>
          <ixy>0</ixy>
          <ixz>0</ixz>
          <iyy>0.001</iyy>
          <iyz>0</iyz>
          <izz>0.00050000000000000001</izz>
        </inertia>
      </inertial>
      <collision name='front_right_wheel_collision'>
        <pose>0 0 0 1.5708 0 0</pose>
        <geometry>
          <cylinder>
            <length>0.029999999999999999</length>
            <radius>0.050000000000000003</radius>
          </cylinder>
        </geometry>
        <surface>
          <contact>
            <ode>
              <kp>1000000</kp>
              <kd>100</kd>
              <max_vel>1</max_vel>
              <min_depth>0.001</min_depth>
            </ode>
          </contact>
          <friction>
            <ode>
              <mu>1.2</mu>
              <mu2>1.2</mu2>
            </ode>
          </friction>
        </surface>
      </collision>
      <visual name='front_right_wheel_visual'>
        <pose>0 0 0 1.5708 0 0</pose>
        <geometry>
          <cylinder>
            <length>0.029999999999999999</length>
            <radius>0.050000000000000003</radius>
          </cylinder>
        </geometry>
        <material>
          <diffuse>0 0 0 1</diffuse>
          <ambient>0 0 0 1</ambient>
        </material>
      </visual>
    </link>
    <joint name='rear_left_wheel_joint' type='revolute'>
      <pose relative_to='base_link'>-0.15 0.125 0 0 0 0</pose>
      <parent>base_link</parent>
      <child>rear_left_wheel</child>
      <axis>
        <xyz>0 1 0</xyz>
        <limit>
          <lower>-10000000000000000</lower>
          <upper>10000000000000000</upper>
        </limit>
        <dynamics>
          <spring_reference>0</spring_reference>
          <spring_stiffness>0</spring_stiffness>
        </dynamics>
      </axis>
    </joint>
    <link name='rear_left_wheel'>
      <pose relative_to='rear_left_wheel_joint'>0 0 0 0 0 0</pose>
      <inertial>
        <pose>0 0 0 0 0 0</pose>
        <mass>0.5</mass>
        <inertia>
          <ixx>0.001</ixx>
          <ixy>0</ixy>
          <ixz>0</ixz>
          <iyy>0.001</iyy>
          <iyz>0</iyz>
          <izz>0.00050000000000000001</izz>
        </inertia>
      </inertial>
      <collision name='rear_left_wheel_collision'>
        <pose>0 0 0 1.5708 0 0</pose>
        <geometry>
          <cylinder>
            <length>0.029999999999999999</length>
            <radius>0.050000000000000003</radius>
          </cylinder>
        </geometry>
        <surface>
          <contact>
            <ode>
              <kp>1000000</kp>
              <kd>100</kd>
              <max_vel>1</max_vel>
              <min_depth>0.001</min_depth>
            </ode>
          </contact>
          <friction>
            <ode>
              <mu>1.2</mu>
              <mu2>1.2</mu2>
            </ode>
          </friction>
        </surface>
      </collision>
      <visual name='rear_left_wheel_visual'>
        <pose>0 0 0 1.5708 0 0</pose>
        <geometry>
          <cylinder>
            <length>0.029999999999999999</length>
            <radius>0.050000000000000003</radius>
          </cylinder>
        </geometry>
        <material>
          <diffuse>0 0 0 1</diffuse>
          <ambient>0 0 0 1</ambient>
        </material>
      </visual>
    </link>
    <joint name='rear_right_wheel_joint' type='revolute'>
      <pose relative_to='base_link'>-0.15 -0.125 0 0 0 0</pose>
      <parent>base_link</parent>
      <child>rear_right_wheel</child>
      <axis>
        <xyz>0 1 0</xyz>
        <limit>
          <lower>-10000000000000000</lower>
          <upper>10000000000000000</upper>
        </limit>
        <dynamics>
          <spring_reference>0</spring_reference>
          <spring_stiffness>0</spring_stiffness>
        </dynamics>
      </axis>
    </joint>
    <link name='rear_right_wheel'>
      <pose relative_to='rear_right_wheel_joint'>0 0 0 0 0 0</pose>
      <inertial>
        <pose>0 0 0 0 0 0</pose>
        <mass>0.5</mass>
        <inertia>
          <ixx>0.001</ixx>
          <ixy>0</ixy>
          <ixz>0</ixz>
          <iyy>0.001</iyy>
          <iyz>0</iyz>
          <izz>0.00050000000000000001</izz>
        </inertia>
      </inertial>
      <collision name='rear_right_wheel_collision'>
        <pose>0 0 0 1.5708 0 0</pose>
        <geometry>
          <cylinder>
            <length>0.029999999999999999</length>
            <radius>0.050000000000000003</radius>
          </cylinder>
        </geometry>
        <surface>
          <contact>
            <ode>
              <kp>1000000</kp>
              <kd>100</kd>
              <max_vel>1</max_vel>
              <min_depth>0.001</min_depth>
            </ode>
          </contact>
          <friction>
            <ode>
              <mu>1.2</mu>
              <mu2>1.2</mu2>
            </ode>
          </friction>
        </surface>
      </collision>
      <visual name='rear_right_wheel_visual'>
        <pose>0 0 0 1.5708 0 0</pose>
        <geometry>
          <cylinder>
            <length>0.029999999999999999</length>
            <radius>0.050000000000000003</radius>
          </cylinder>
        </geometry>
        <material>
          <diffuse>0 0 0 1</diffuse>
          <ambient>0 0 0 1</ambient>
        </material>
      </visual>
    </link>
    <plugin name='gz::sim::systems::JointStatePublisher' filename='gz-sim-joint-state-publisher-system'>
      <topic>joint_states</topic>
    </plugin>
    <plugin name='gz::sim::systems::JointController' filename='gz-sim-joint-controller-system'>
      <joint_name>rear_left_wheel_joint</joint_name>
      <topic>rear_left_wheel/cmd_vel</topic>
      <p_gain>1.0</p_gain>
      <i_gain>0.1</i_gain>
      <d_gain>0.01</d_gain>
      <i_max>1.0</i_max>
      <i_min>-1.0</i_min>
      <cmd_max>100.0</cmd_max>
      <cmd_min>-100.0</cmd_min>
    </plugin>
    <plugin name='gz::sim::systems::JointController' filename='gz-sim-joint-controller-system'>
      <joint_name>rear_right_wheel_joint</joint_name>
      <topic>rear_right_wheel/cmd_vel</topic>
      <p_gain>1.0</p_gain>
      <i_gain>0.1</i_gain>
      <d_gain>0.01</d_gain>
      <i_max>1.0</i_max>
      <i_min>-1.0</i_min>
      <cmd_max>100.0</cmd_max>
      <cmd_min>-100.0</cmd_min>
    </plugin>
    <plugin name='gz::sim::systems::JointPositionController' filename='gz-sim-joint-position-controller-system'>
      <joint_name>front_left_wheel_steering_joint</joint_name>
      <topic>front_left_steering/cmd_pos</topic>
      <p_gain>10.0</p_gain>
      <i_gain>0.1</i_gain>
      <d_gain>0.5</d_gain>
      <i_max>1.0</i_max>
      <i_min>-1.0</i_min>
      <cmd_max>100.0</cmd_max>
      <cmd_min>-100.0</cmd_min>
    </plugin>
    <plugin name='gz::sim::systems::JointPositionController' filename='gz-sim-joint-position-controller-system'>
      <joint_name>front_right_wheel_steering_joint</joint_name>
      <topic>front_right_steering/cmd_pos</topic>
      <p_gain>10.0</p_gain>
      <i_gain>0.1</i_gain>
      <d_gain>0.5</d_gain>
      <i_max>1.0</i_max>
      <i_min>-1.0</i_min>
      <cmd_max>100.0</cmd_max>
      <cmd_min>-100.0</cmd_min>
    </plugin>
    <plugin name='ignition::gazebo::systems::PosePublisher' filename='libignition-gazebo-pose-publisher-system.so'>
      <publish_link_pose>true</publish_link_pose>
      <publish_sensor_pose>false</publish_sensor_pose>
      <publish_collision_pose>false</publish_collision_pose>
      <publish_visual_pose>false</publish_visual_pose>
      <publish_nested_model_pose>false</publish_nested_model_pose>
      <update_frequency>50</update_frequency>
    </plugin>
    <frame name='imu_joint' attached_to='base_link'>
      <pose>0 0 0.05 0 -0 0</pose>
    </frame>
    <frame name='imu_link' attached_to='imu_joint'/>
    <frame name='lidar_joint' attached_to='base_link'>
      <pose>0 0 0.1 0 -0 0</pose>
    </frame>
    <frame name='lidar_link' attached_to='lidar_joint'/>
  </model>
</sdf>
